Workbook

Sheet Raw Data
A1: Post ID | B1: University | C1: Post Date | D1: Month | E1: Year | F1: Instagram URL | G1: Post Type | H1: Recruitment-Oriented? | I1: Primary Theme | J1: Secondary Theme | K1: Marketing Approach | L1: CTA Present? | M1: Likes | N1: Comments | O1: Caption Summary
A2: UOT001 | B2: University of Toronto | C2: 45677 | D2: =IF(C2="","",TEXT(C2,"mmmm")) -> January | E2: =IF(C2="","",YEAR(C2)) -> 2025 | F2: https://www.instagram.com/reel/DFDbR9zSpaG/?utm_source=ig_web_copy_link&igsh=MzRlODBiNWFlZA== | G2: Reel | H2: Yes | I2: Student Experience | J2: Campus Life | K2: Emotional Storytelling | L2: Yes | M2: 574 | N2: 17 | O2: We’re asking @uoftmedicine & @uoftrunclub’s Emily Nguyen about her rapid fire faves at #UofT! Have you seen our first #MyUofT video? Be sure to check it out!
A3: UOT002 | B3: University of Toronto | C3: 45684 | D3: =IF(C3="","",TEXT(C3,"mmmm")) -> January | E3: =IF(C3="","",YEAR(C3)) -> 2025 | F3: https://www.instagram.com/p/DFV2mHuyw7n/?utm_source=ig_web_copy_link&igsh=MzRlODBiNWFlZA== | G3: Image | H3: Yes | I3: Rankings & Achievements | J3: Academic Programs | K3: Reputation Building | L3: Yes | M3: 1513 | N3: 17 | O3: #UofT ranked first in Canada in all 11 subjects tracked by Times Higher Education’s World University Rankings by Subject 2025 – and is one of only six universities in the world to rank in the top 30 across the board. 🍁
A4: UOT003 | B4: University of Toronto | C4: 45687 | D4: =IF(C4="","",TEXT(C4,"mmmm")) -> January | E4: =IF(C4="","",YEAR(C4)) -> 2025 | F4: https://www.instagram.com/reel/DFdo9ZNv8UA/?utm_source=ig_web_copy_link&igsh=MzRlODBiNWFlZA== | G4: Reel | H4: Yes | I4: Alumni Success | J4: Events | K4: Community Engagement | L4: Yes | M4: 248 | N4: 3 | O4: What if sharing your expertise could spark a positive change? With more than 23,000 #UofTalumni already stepping up as mentors and volunteers, our #UofT community is powered by the passion and dedication of our grads.
A5: UOT004 | B5: University of Toronto | C5: 45693 | D5: =IF(C5="","",TEXT(C5,"mmmm")) -> February | E5: =IF(C5="","",YEAR(C5)) -> 2025 | F5: https://www.instagram.com/p/DFtOatUykUC/?utm_source=ig_web_copy_link&igsh=MzRlODBiNWFlZA== | G5: Image | H5: Yes | I5: Research & Innovation | J5: Rankings & Achievements | K5: Reputation Building | L5: Yes | M5: 1031 | N5: 16 | O5: #UofT is among the world’s top 10 universities powering global innovation in critical areas like technology, health care, sustainability and economic development, according to international data analytics company Clarivate.
A6: UOT005 | B6: University of Toronto | C6: 45699 | D6: =IF(C6="","",TEXT(C6,"mmmm")) -> February | E6: =IF(C6="","",YEAR(C6)) -> 2025 | F6: https://www.instagram.com/reel/DF8FBerRF8m/?utm_source=ig_web_copy_link&igsh=MzRlODBiNWFlZA== | G6: Reel | H6: Yes | I6: Student Experience | J6: Campus Life | K6: Student Testimonial | L6: Yes | M6: 2628 | N6: 33 | O6: A day in the life of a @uoftims & #UofT PhD student, @sciencewithsajee!
A7: UOT006 | B7: University of Toronto | C7: 45702 | D7: =IF(C7="","",TEXT(C7,"mmmm")) -> February | E7: =IF(C7="","",YEAR(C7)) -> 2025 | F7: https://www.instagram.com/p/DGDu9TwRvKz/?utm_source=ig_web_copy_link&igsh=MzRlODBiNWFlZA== | G7: Carousel | H7: Yes | I7: Diversity & Inclusion | J7: Research & Innovation | K7: Emotional Storytelling | L7: Yes | M7: 1516 | N7: 9 | O7: Diagnosed with autism, he couldn’t speak or signal his thoughts. But everything changed when he learned to communicate through a letter board. What followed stunned his family. Now, he is helping #UofT neuroscientist Morgan Barense with her research @uoftpsychology using brain scans into non-speaking autism.
A8: UOT007 | B8: University of Toronto | C8: 45729 | D8: =IF(C8="","",TEXT(C8,"mmmm")) -> March | E8: =IF(C8="","",YEAR(C8)) -> 2025 | F8: https://www.instagram.com/reel/DHJab1PRh1X/?utm_source=ig_web_copy_link&igsh=MzRlODBiNWFlZA== | G8: Reel | H8: Yes | I8: Alumni Success | J8: Events | K8: Community Engagement | L8: Yes | M8: 1047 | N8: 73 | O8: This is @uoftstartup’s #UofTEntWeek, founder style! Follow #UofT alumna & Toothpod founder @vishar.y as she explores everything U of T Entrepreneurship has to offer, including her personal advice on getting started.
A9: UOT008 | B9: University of Toronto | C9: 45733 | D9: =IF(C9="","",TEXT(C9,"mmmm")) -> March | E9: =IF(C9="","",YEAR(C9)) -> 2025 | F9: https://www.instagram.com/reel/DHT7iTYxaMb/?utm_source=ig_web_copy_link&igsh=MzRlODBiNWFlZA== | G9: Reel | H9: Yes | I9: Diversity & Inclusion | J9: Alumni Success | K9: Inspirational | L9: No | M9: 2463 | N9: 59 | O9: 11 languages? 🤯 Recent #UofT alumni and hyperpolyglot @xinyi_limx shows us her appreciation for the diversity and rich culture that Toronto has to offer. #MyUofT
A10: UOT009 | B10: University of Toronto | C10: 45736 | D10: =IF(C10="","",TEXT(C10,"mmmm")) -> March | E10: =IF(C10="","",YEAR(C10)) -> 2025 | F10: https://www.instagram.com/reel/DHbOdPjyScp/?utm_source=ig_web_copy_link&igsh=MzRlODBiNWFlZA== | G10: Reel | H10: Yes | I10: Admissions | J10: Student Support Services | K10: Call-to-Action | L10: Yes | M10: 537 | N10: 11 | O10: Did you get an acceptance letter from #UofT? Congratulations! 🎉 We want to see your excitement to start your journey with us next year! DM us or post a video with #UofTBound tagging @futureuoft, @uoft and your campus @utsc or @uoftmississauga for your chance to be featured on our accounts!
A11: UOT010 | B11: University of Toronto | C11: 45748 | D11: =IF(C11="","",TEXT(C11,"mmmm")) -> April | E11: =IF(C11="","",YEAR(C11)) -> 2025 | F11: https://www.instagram.com/p/DH6YEVQOf-Z/?utm_source=ig_web_copy_link&igsh=MzRlODBiNWFlZA== | G11: Carousel | H11: Yes | I11: Admissions | J11: Academic Programs | K11: Promotional | L11: Yes | M11: 2233 | N11: 20 | O11: #UTM March Open House was a memorable day filled with opportunities! 💙 .
A12: UOT011 | B12: University of Toronto | C12: 45751 | D12: =IF(C12="","",TEXT(C12,"mmmm")) -> April | E12: =IF(C12="","",YEAR(C12)) -> 2025 | F12: https://www.instagram.com/reel/DIB-jGhRYlB/?utm_source=ig_web_copy_link&igsh=MzRlODBiNWFlZA== | G12: Reel | H12: Yes | I12: Campus Facilities | J12: Student Experience | K12: Emotional Storytelling | L12: Yes | M12: 1645 | N12: 14 | O12: After being named #UofT’s 17th president on March 26, Melanie Woodin met with students, staff, faculty and senior leaders across U of T’s three campuses during a whirlwind two-day tour. 💙
A13: UOT012 | B13: University of Toronto | C13: 45772 | D13: =IF(C13="","",TEXT(C13,"mmmm")) -> April | E13: =IF(C13="","",YEAR(C13)) -> 2025 | F13: https://www.instagram.com/reel/DI37WR7tdJv/?utm_source=ig_web_copy_link&igsh=MzRlODBiNWFlZA== | G13: Reel | H13: Yes | I13: Admissions | J13: Student Experience | K13: Emotional Storytelling | L13: No | M13: 3952 | N13: 56 | O13: his is the moment when @dentistrywithdal found out she was #UofTBound! 💙 She’ll be attending @uoftdentistry this fall. We’re so excited to have you at #UofT, @daliaprovad!
... A17: UOT016 | B17: University of Toronto | C17: 45809 | D17: =IF(C17="","",TEXT(C17,"mmmm")) -> June | E17: =IF(C17="","",YEAR(C17)) -> 2025 | F17: https://www.instagram.com/reel/DKXIit-OuyH/?utm_source=ig_web_copy_link&igsh=MzRlODBiNWFlZA== | G17: Reel | H17: Yes | I17: Alumni Success | J17: Campus Life | K17: Community Engagement | L17: Yes | M17: 606 | N17: 8 | O17: We asked, you answered. Your @UofT memories, old and new, gave us all the feels. 💙 This year at #UofTReunion, alumni across all three campuses celebrated every moment, big and small. Thank you to our alumni and friends for bringing the energy (and the stories)!
A18: UOT017 | B18: University of Toronto | C18: 45825 | D18: June | E18: 2025 | F18: https://www.instagram.com/p/DLAZUomgiBI/?utm_source=ig_web_copy_link&igsh=MzRlODBiNWFlZA== | G18: Image | H18: Yes | I18: Academic Programs | J18: Research & Innovation | K18: Promotional | L18: Yes | M18: 625 | N18: 8 | O18: Becoming ‘AI-ready’: #UofT’s task force on artificial intelligence releases recommendations. The task force’s report aims to establish U of T as a post-secondary leader in its implementation of AI across its operations. Learn more at our link in bio or at uoft.me/aitf.
A19: UOT018 | B19: University of Toronto | C19: 45832 | D19: =IF(C19="","",TEXT(C19,"mmmm")) -> June | E19: =IF(C19="","",YEAR(C19)) -> 2025 | F19: https://www.instagram.com/reel/DLSfp-YAoOW/?utm_source=ig_web_copy_link&igsh=MzRlODBiNWFlZA== | G19: Reel | H19: Yes | I19: Diversity & Inclusion | J19: Student Experience | K19: Informational | L19: No | M19: 366 | N19: 26 | O19: The Black Students’ Association celebrated #UofT’s Class of 2025 at @harthouseuoft earlier this month. The annual, student-run “Black Grad” celebration recognizes the resilience, diversity & academic accomplishments of Black students graduating from U of T’s three campuses. 🎉 #UofTGrad25
A20: UOT019 | B20: University of Toronto | C20: 45842 | D20: =IF(C20="","",TEXT(C20,"mmmm")) -> July | E20: =IF(C20="","",YEAR(C20)) -> 2025 | F20: https://www.instagram.com/reel/DLsRmpdA1zs/?utm_source=ig_web_copy_link&igsh=MzRlODBiNWFlZA== | G20: Reel | H20: Yes | I20: Events | J20: Other | K20: Promotional | L20: Yes | M20: 323 | N20: 7 | O20: #UofT took centre stage at the first ever Toronto Tech Week this year. Some of the most renowned names in AI and other cutting-edge fields, from Nobel laureate Geoffrey Hinton to self-driving whiz Raquel Urtasun, were featured in panel discussions, fireside chats, startup demos and other events from June 23-27.
A21: UOT020 | B21: University of Toronto | C21: 45847 | D21: =IF(C21="","",TEXT(C21,"mmmm")) -> July | E21: =IF(C21="","",YEAR(C21)) -> 2025 | F21: https://www.instagram.com/p/DL5NrRFNftG/?utm_source=ig_web_copy_link&igsh=MzRlODBiNWFlZA== | G21: Image | H21: Yes | I21: Student Experience | J21: Career Opportunities | K21: Promotional | L21: Yes | M21: 512 | N21: 10 | O21: What happens when passion meets purpose? @oiseuoft student Shezadi Khushal’s #UofT journey is driven by a deep commitment to equity in education. Now, she’s working to make the system better for everyone.
A22: UOT021 | B22: University of Toronto | C22: 45856 | D22: =IF(C22="","",TEXT(C22,"mmmm")) -> July | E22: =IF(C22="","",YEAR(C22)) -> 2025 | F22: https://www.instagram.com/reel/DMQN3rzucXD/?utm_source=ig_web_copy_link&igsh=MzRlODBiNWFlZA== | G22: Reel | H22: Yes | I22: Campus Facilities | J22: Rankings & Achievements | K22: Reputation Building | L22: Yes | M22: 1132 | N22: 14 | O22: What does the future of dental education look like? From analog tools to advanced tech, #UofT Dentistry’s training spaces have come a long way.
A23: UOT022 | B23: University of Toronto | C23: 45877 | D23: =IF(C23="","",TEXT(C23,"mmmm")) -> August | E23: =IF(C23="","",YEAR(C23)) -> 2025 | F23: https://www.instagram.com/p/DNGc3jhRA7u/?utm_source=ig_web_copy_link&igsh=MzRlODBiNWFlZA== | G23: Image | H23: Yes | I23: Campus Life | J23: Campus Facilities | K23: Informational | L23: Yes | M23: 3763 | N23: 29 | O23: New #UofT students – the countdown is on! 💙 There are tons of ways to get involved and kick off your university journey across all three campuses. Check out these resources as you start your new journey with confidence ⬇️
A24: UOT023 | B24: University of Toronto | C24: 45891 | D24: =IF(C24="","",TEXT(C24,"mmmm")) -> August | E24: =IF(C24="","",YEAR(C24)) -> 2025 | F24: https://www.instagram.com/reel/DNqgCcQx-uw/?utm_source=ig_web_copy_link&igsh=MzRlODBiNWFlZA== | G24: Reel | H24: Yes | I24: Student Experience | J24: Campus Life | K24: Promotional | L24: Yes | M24: 657 | N24: 8 | O24: PART 1 📚 We asked #UofT students to share some tips on things they wish they knew before starting university? 🤔💙 #MyUofT
A25: UOT024 | B25: University of Toronto | C25: 45895 | D25: =IF(C25="","",TEXT(C25,"mmmm")) -> August | E25: =IF(C25="","",YEAR(C25)) -> 2025 | F25: https://www.instagram.com/reel/DN1FAXx3g0g/?utm_source=ig_web_copy_link&igsh=MzRlODBiNWFlZA== | G25: Reel | H25: Yes | I25: Academic Programs | J25: Admissions | K25: Promotional | L25: Yes | M25: 2766 | N25: 23 | O25: Guess which nursing school is ranked first in Canada and fourth in the world? @uoftnursing is leading the way, from award-winning research and a state-of-the-art simulation lab to groundbreaking programs and placements at Canada’s top health-care institutions. Watch student Morayo Aladejana walk us through why Bloomberg Nursing is best in class.
A26: UOT025 | B26: University of Toronto | C26: 45539 | D26: =IF(C26="","",TEXT(C26,"mmmm")) -> September | E26: =IF(C26="","",YEAR(C26)) -> 2024 | F26: https://www.instagram.com/reel/C_gAY05uOuR/?utm_source=ig_web_copy_link&igsh=MzRlODBiNWFlZA== | G26: Reel | H26: Yes | I26: Alumni Success | J26: Campus Life | K26: Emotional Storytelling | L26: No | M26: 1134 | N26: 29 | O26: Who remembers their first day at #UofT like it was yesterday? It’s certainly top of mind for #UofTalumni Ali Kehl, @viccollege’s campus life coordinator, because it’s now her job to help undergrads settle in and get involved. As Vic celebrates 100 years of student engagement in 2024, we asked Ali to share her favourite spots around the college she still calls home.
A27: UOT026 | B27: University of Toronto | C27: 45558 | D27: =IF(C27="","",TEXT(C27,"mmmm")) -> September | E27: =IF(C27="","",YEAR(C27)) -> 2024 | F27: https://www.instagram.com/p/DARSyHePe8t/?utm_source=ig_web_copy_link&igsh=MzRlODBiNWFlZA== | G27: Image | H27: Yes | I27: Scholarships & Financial Aid | J27: Campus Facilities | K27: Informational | L27: Yes | M27: 2430 | N27: 9 | O27: A $25-million gift from Myron and Berna Garron will contribute to the construction of a new state-of-the-art facility at UTSC that will house the Scarborough Academy of Medicine and Integrated Health (SAMIH). @uoft will name the new building the Myron and Berna Garron Health Sciences Complex, in honour of the Garrons’ exceptional generosity.
A28: UOT027 | B28: University of Toronto | C28: 45561 | D28: =IF(C28="","",TEXT(C28,"mmmm")) -> September | E28: =IF(C28="","",YEAR(C28)) -> 2024 | F28: https://www.instagram.com/reel/DAYquplxdS_/?utm_source=ig_web_copy_link&igsh=MzRlODBiNWFlZA== | G28: Reel | H28: Yes | I28: Student Experience | J28: International Students | K28: Promotional | L28: Yes | M28: 2380 | N28: 33 | O28: From why they chose #UofT to making the most of your first year — international students share their experiences 💙 #UofTBackToSchool
A29: UOT028 | B29: University of Toronto | C29: 45567 | D29: =IF(C29="","",TEXT(C29,"mmmm")) -> October | E29: =IF(C29="","",YEAR(C29)) -> 2024 | F29: https://www.instagram.com/reel/DAoiZorSwTY/?utm_source=ig_web_copy_link&igsh=MzRlODBiNWFlZA== | G29: Reel | H29: Yes | I29: Student Experience | J29: International Students | K29: Promotional | L29: Yes | M29: 1095 | N29: 37 | O29: Screening across #UofT this fall is a documentary that highlights the journey of international students to our three campuses. International Students: First 48 Hours in Canada is a 22-minute film directed by Cal Campos, capturing the excitement and challenges of packing, traveling, and finally setting foot on each campus.
A30: UOT029 | B30: University of Toronto | C30: 45581 | D30: =IF(C30="","",TEXT(C30,"mmmm")) -> October | E30: =IF(C30="","",YEAR(C30)) -> 2024 | F30: https://www.instagram.com/p/DBMdpOWSbwV/?utm_source=ig_web_copy_link&igsh=MzRlODBiNWFlZA== | G30: Image | H30: Yes | I30: Rankings & Achievements | J30: Academic Programs | K30: Informational | L30: Yes | M30: 4695 | N30: 37 | O30: #UofT is once again first in Canada and 21st globally in the prestigious World Reputation Rankings by @timeshighered 🌎 The ranking assesses schools across five broad pillars: teaching, research environment, research quality, industry and international outlook.
... A87: YRK014 | B87: York University | C87: 45797 | D87: =IF(C87="","",TEXT(C87,"mmmm")) -> May | E87: =IF(C87="","",YEAR(C87)) -> 2025 | F87: https://www.instagram.com/reel/DJ4ynQPyisG/?utm_source=ig_web_copy_link&igsh=MzRlODBiNWFlZA== | G87: Reel | H87: Yes | I87: Student Experience | J87: Student Clubs & Organizations | K87: Community Engagement | L87: Yes | M87: 294 | N87: 6 | O87: York U Lions X @Raptors takeover and the IBM Practice Court 🏀
A88: YRK015 | B88: York University | C88: 45792 | D88: =IF(C88="","",TEXT(C88,"mmmm")) -> May | E88: =IF(C88="","",YEAR(C88)) -> 2025 | F88: https://www.instagram.com/reel/DJrwYjfR7po/?utm_source=ig_web_copy_link&igsh=MzRlODBiNWFlZA== | G88: Reel | H88: Yes | I88: Alumni Success | J88: Rankings & Achievements | K88: Inspirational | L88: No | M88: NA | N88: NA | O88: Congratulations to York’s 2025 Top 30 Alumni Under 30 recipients! This group of remarkable young alumni are making a global impact and inspiring the next generation of leaders. #YorkUTop30 #YorkU
A89: YRK016 | B89: York University | C89: 45825 | D89: =IF(C89="","",TEXT(C89,"mmmm")) -> June | E89: =IF(C89="","",YEAR(C89)) -> 2025 | F89: https://www.instagram.com/p/DLAfCO8R2aT/?utm_source=ig_web_copy_link&igsh=MzRlODBiNWFlZA== | G89: Image | H89: Yes | I89: Student Experience | J89: Events | K89: Inspirational | L89: No | M89: 1217 | N89: 10 | O89: Meet Aila Narimani, this year’s recipient of York U’s prestigious Murray G. Ross Award! From student governance to global advocacy, Aila’s impact has been profound, and now she’s setting her sights on a future in dentistry rooted in care and accessibility. |
A90: YRK017 | B90: York University | C90: 45827 | D90: =IF(C90="","",TEXT(C90,"mmmm")) -> June | E90: =IF(C90="","",YEAR(C90)) -> 2025 | F90: https://www.instagram.com/reel/DLFiIXNAgBU/?utm_source=ig_web_copy_link&igsh=MzRlODBiNWFlZA== | G90: Reel | H90: Yes | I90: Student Experience | J90: International Students | K90: Inspirational | L90: No | M90: 404 | N90: 26 | O90: From Congo to Canada, one father’s dream became a family legacy. Learn more about the Serufuli family and their shared journey of resilience and education. Since 2018, eight of the nine siblings have attended Glendon Campus at York U | #YorkUConvo
A91: YRK018 | B91: York University | C91: 45833 | D91: =IF(C91="","",TEXT(C91,"mmmm")) -> June | E91: =IF(C91="","",YEAR(C91)) -> 2025 | F91: https://www.instagram.com/reel/DLU1-pxg3ow/?utm_source=ig_web_copy_link&igsh=MzRlODBiNWFlZA== | G91: Reel | H91: Yes | I91: Student Experience | J91: Rankings & Achievements | K91: Emotional Storytelling | L91: No | M91: 1150 | N91: 13 | O91: Former Raptors head coach Nick Nurse received an honorary doctorate at convocation last week! Hear what he had to share with the class of 2025! | #YorkUConvo @thenicknurse
A92: YRK019 | B92: York University | C92: 45862 | D92: =IF(C92="","",TEXT(C92,"mmmm")) -> July | E92: =IF(C92="","",YEAR(C92)) -> 2025 | F92: https://www.instagram.com/p/DMfqtIdO7SA/?utm_source=ig_web_copy_link&igsh=MzRlODBiNWFlZA== | G92: Carousel | H92: Yes | I92: Campus Facilities | J92: Campus Life | K92: Emotional Storytelling | L92: No | M92: 1110 | N92: 5 | O92: ow It Started vs. How It's Going: Sobeys Stadium at York U is the home of Canada's top tennis tournament, the National Bank Open, which begins this weekend! The stadium was built to replace the old National Tennis Centre, which was located on the north east side of Keele Campus, and was demolished in 2003.
A93: YRK020 | B93: York University | C93: 45867 | D93: =IF(C93="","",TEXT(C93,"mmmm")) -> July | E93: =IF(C93="","",YEAR(C93)) -> 2025 | F93: https://www.instagram.com/reel/DMs8Xn-xUHs/?utm_source=ig_web_copy_link&igsh=MzRlODBiNWFlZA== | G93: Reel | H93: Yes | I93: Campus Facilities | J93: Academic Programs | K93: Promotional | L93: No | M93: 1370 | N93: 34 | O93: York U celebrates another milestone with the unveiling of a new sign for the future School of Medicine building next to Cortellucci Vaughan Hospital, and signed a partnership with the Ontario Centre of Innovation toward fostering health-care innovation. | #YorkUMedicine
A94: YRK021 | B94: York University | C94: 45868 | D94: =IF(C94="","",TEXT(C94,"mmmm")) -> July | E94: =IF(C94="","",YEAR(C94)) -> 2025 | F94: https://www.instagram.com/p/DMvOVgiOTNg/?utm_source=ig_web_copy_link&igsh=MzRlODBiNWFlZA== | G94: Image | H94: Yes | I94: Student Experience | J94: Campus Life | K94: Community Engagement | L94: Yes | M94: 713 | N94: 19 | O94: There’s something special about the bonds formed on campus, like an unlikely friendship between a lion and a raptor. Tag your York U bestie in the comments. | #InternationalFriendshipDay
A95: YRK022 | B95: York University | C95: 45895 | D95: =IF(C95="","",TEXT(C95,"mmmm")) -> August | E95: =IF(C95="","",YEAR(C95)) -> 2025 | F95: https://www.instagram.com/reel/DN0iBFT5BpY/?utm_source=ig_web_copy_link&igsh=MzRlODBiNWFlZA== | G95: Reel | H95: Yes | I95: Campus Life | J95: Student Experience | K95: Community Engagement | L95: Yes | M95: 342 | N95: 7 | O95: eady to meet like-minded individuals and get ready for campus life? Make the beginning of your year memorable by joining the many orientation events happening at York U this week!
A96: YRK023 | B96: York University | C96: 45897 | D96: =IF(C96="","",TEXT(C96,"mmmm")) -> August | E96: =IF(C96="","",YEAR(C96)) -> 2025 | F96: https://www.instagram.com/reel/DN6Uxvwipn-/?utm_source=ig_web_copy_link&igsh=MzRlODBiNWFlZA== | G96: Reel | H96: Yes | I96: Campus Life | J96: Campus Facilities | K96: Community Engagement | L96: Yes | M96: 1550 | N96: 14 | O96: Move-In Day at York University was a huge success! We welcomed over 1400 student residents across all three campuses. Thank you to the York U community for helping make our new lions feel safe, supported, and at home. 📦 | #StartStrongYU
A97: YRK024 | B97: York University | C97: 45876 | D97: =IF(C97="","",TEXT(C97,"mmmm")) -> August | E97: =IF(C97="","",YEAR(C97)) -> 2025 | F97: https://www.instagram.com/reel/DNDnHcTBTUm/?utm_source=ig_web_copy_link&igsh=MzRlODBiNWFlZA== | G97: Reel | H97: Yes | I97: Campus Life | J97: Student Experience | K97: Emotional Storytelling | L97: No | M97: 535 | N97: 13 | O97: Incoming students, we are excited to welcome you to our York U campuses this September. Until then, we hope you are enjoying the summer.
A98: YRK025 | B98: York University | C98: 45541 | D98: =IF(C98="","",TEXT(C98,"mmmm")) -> September | E98: =IF(C98="","",YEAR(C98)) -> 2024 | F98: https://www.instagram.com/reel/C_lcsTASsB0/?utm_source=ig_web_copy_link&igsh=MzRlODBiNWFlZA== | G98: Reel | H98: Yes | I98: Campus Life | J98: Events | K98: Community Engagement | L98: No | M98: 1824 | N98: 20 | O98: We had a fantastic time at our orientation week events alongside our incoming first year students! We can’t wait to make more memories together this school year, Lions! 🦁 📓 | #YorkU #StartStrongYU
A99: YRK026 | B99: York University | C99: 45548 | D99: =IF(C99="","",TEXT(C99,"mmmm")) -> September | E99: =IF(C99="","",YEAR(C99)) -> 2024 | F99: https://www.instagram.com/reel/C_3purKy9fS/?utm_source=ig_web_copy_link&igsh=MzRlODBiNWFlZA== | G99: Reel | H99: Yes | I99: Student Experience | J99: Academic Programs | K99: Student Testimonial | L99: Yes | M99: 1013 | N99: 32 | O99: We checked in with York U students to find out what programs they are taking and here are their choices! Let us know what program you are taking in the comments below. 📚💻 | #StartStrongYU #YorkU
...

Sheet Lists
A1: University of Toronto | B1: Image | C1: Yes | D1: Academic Programs | E1: Informational
A2: McMaster University | B2: Carousel | C2: No | D2: Admissions | E2: Promotional
A3: York University | B3: Reel | D3: Student Experience | E3: Emotional Storytelling
A4: Toronto Metropolitan University | B4: Video | D4: Campus Life | E4: Student Testimonial
A5: University of Waterloo | D5: Scholarships & Financial Aid | E5: Reputation Building
D6: Career Opportunities | E6: Community Engagement
D7: Research & Innovation | E7: Call-to-Action
D8: Student Support Services | E8: Inspirational
D9: Campus Facilities
D10: Diversity & Inclusion
D11: International Students
D12: Student Clubs & Organizations
D13: Events
D14: Rankings & Achievements
D15: Alumni Success

Sheet Analysis Data
A1: Post ID | B1: University | C1: Post Date | D1: Month | E1: Year | F1: Instagram URL | G1: Post Type | H1: Recruitment-Oriented? | I1: Primary Theme | J1: Secondary Theme | K1: Marketing Approach | L1: CTA Present? | M1: Likes | N1: Comments | O1: Caption Summary | P1: Primary Theme Group | Q1: Secondary Theme Group | R1: Approach Group | S1: Duplicate ID Check | T1: Duplicate URL Check | U1: Date Check | V1: Record Note
A2: UOT001 | B2: University of Toronto | C2: 45677 | D2: =IF(C2="","",TEXT(C2,"mmmm")) -> January | E2: =IF(C2="","",YEAR(C2)) -> 2025 | F2: https://www.instagram.com/reel/DFDbR9zSpaG/?utm_source=ig_web_copy_link&igsh=MzRlODBiNWFlZA== | G2: Reel | H2: Yes | I2: Student Experience | J2: Campus Life | K2: Emotional Storytelling | L2: Yes | M2: 574 | N2: 17 | O2: We’re asking @uoftmedicine & @uoftrunclub’s Emily Nguyen about her rapid fire faves at #UofT! Have you seen our first #MyUofT video? Be sure to check it out! | P2: =IF(OR(I2="Student Experience",I2="Campus Life",I2="Campus Facilities",I2="Student Clubs & Organizations",I2="Events",I2="Student Support Services",I2="Diversity & Inclusion",I2="International Students"),"Student Experience & Campus",IF(OR(I2="Academic Programs",I2="Admissions",I2="Scholarships & Financial Aid"),"Academic & Admissions",IF(OR(I2="Career Opportunities",I2="Alumni Success"),"Career & Alumni",IF(I2="Research & Innovation","Research & Innovation",IF(I2="Rankings & Achievements","Institutional Reputation","Other"))))) -> Student Experience & Campus | Q2: =IF(OR(J2="Student Experience",J2="Campus Life",J2="Campus Facilities",J2="Student Clubs & Organizations",J2="Events",J2="Student Support Services",J2="Diversity & Inclusion",J2="International Students"),"Student Experience & Campus",IF(OR(J2="Academic Programs",J2="Admissions",J2="Scholarships & Financial Aid"),"Academic & Admissions",IF(OR(J2="Career Opportunities",J2="Alumni Success"),"Career & Alumni",IF(J2="Research & Innovation","Research & Innovation",IF(J2="Rankings & Achievements","Institutional Reputation","Other"))))) -> Student Experience & Campus | R2: =IF(K2="Informational","Informational",IF(OR(K2="Promotional",K2="Call-to-Action"),"Promotional/Conversion",IF(K2="Reputation Building","Reputation-focused","Engagement/Relationship"))) -> Engagement/Relationship | S2: =IF(COUNTIF($A$2:$A$181,A2)>1,"Duplicate","OK") -> OK | T2: =IF(COUNTIF($F$2:$F$181,F2)>1,"Duplicate","OK") -> OK | U2: =IF(AND(TEXT(C2,"mmmm")=D2,YEAR(C2)=E2),"OK","Mismatch") -> OK | V2: =IF(OR(M2="NA",N2="NA"),"Likes/comments unavailable",IF(I2=J2,"Primary and secondary themes identical","OK")) -> OK
A3: UOT002 | B3: University of Toronto | C3: 45684 | D3: January | E3: =IF(C3="","",YEAR(C3)) -> 2025 | F3: https://www.instagram.com/p/DFV2mHuyw7n/?utm_source=ig_web_copy_link&igsh=MzRlODBiNWFlZA== | G3: Image | H3: Yes | I3: Rankings & Achievements | J3: Academic Programs | K3: Reputation Building | L3: Yes | M3: 1513 | N3: 17 | O3: #UofT ranked first in Canada in all 11 subjects tracked by Times Higher Education’s World University Rankings by Subject 2025 – and is one of only six universities in the world to rank in the top 30 across the board. 🍁 | P3: =IF(OR(I3="Student Experience",I3="Campus Life",I3="Campus Facilities",I3="Student Clubs & Organizations",I3="Events",I3="Student Support Services",I3="Diversity & Inclusion",I3="International Students"),"Student Experience & Campus",IF(OR(I3="Academic Programs",I3="Admissions",I3="Scholarships & Financial Aid"),"Academic & Admissions",IF(OR(I3="Career Opportunities",I3="Alumni Success"),"Career & Alumni",IF(I3="Research & Innovation","Research & Innovation",IF(I3="Rankings & Achievements","Institutional Reputation","Other"))))) -> Institutional Reputation | Q3: =IF(OR(J3="Student Experience",J3="Campus Life",J3="Campus Facilities",J3="Student Clubs & Organizations",J3="Events",J3="Student Support Services",J3="Diversity & Inclusion",J3="International Students"),"Student Experience & Campus",IF(OR(J3="Academic Programs",J3="Admissions",J3="Scholarships & Financial Aid"),"Academic & Admissions",IF(OR(J3="Career Opportunities",J3="Alumni Success"),"Career & Alumni",IF(J3="Research & Innovation","Research & Innovation",IF(J3="Rankings & Achievements","Institutional Reputation","Other"))))) -> Academic & Admissions | R3: =IF(K3="Informational","Informational",IF(OR(K3="Promotional",K3="Call-to-Action"),"Promotional/Conversion",IF(K3="Reputation Building","Reputation-focused","Engagement/Relationship"))) -> Reputation-focused | S3: =IF(COUNTIF($A$2:$A$181,A3)>1,"Duplicate","OK") -> OK | T3: =IF(COUNTIF($F$2:$F$181,F3)>1,"Duplicate","OK") -> OK | U3: =IF(AND(TEXT(C3,"mmmm")=D3,YEAR(C3)=E3),"OK","Mismatch") -> OK | V3: =IF(OR(M3="NA",N3="NA"),"Likes/comments unavailable",IF(I3=J3,"Primary and secondary themes identical","OK")) -> OK
A4: UOT003 | B4: University of Toronto | C4: 45687 | D4: January | E4: 2025 | F4: https://www.instagram.com/reel/DFdo9ZNv8UA/?utm_source=ig_web_copy_link&igsh=MzRlODBiNWFlZA== | G4: Reel | H4: Yes | I4: Alumni Success | J4: Events | K4: Community Engagement | L4: Yes | M4: 248 | N4: 3 | O4: What if sharing your expertise could spark a positive change? With more than 23,000 #UofTalumni already stepping up as mentors and volunteers, our #UofT community is powered by the passion and dedication of our grads. | P4: =IF(OR(I4="Student Experience",I4="Campus Life",I4="Campus Facilities",I4="Student Clubs & Organizations",I4="Events",I4="Student Support Services",I4="Diversity & Inclusion",I4="International Students"),"Student Experience & Campus",IF(OR(I4="Academic Programs",I4="Admissions",I4="Scholarships & Financial Aid"),"Academic & Admissions",IF(OR(I4="Career Opportunities",I4="Alumni Success"),"Career & Alumni",IF(I4="Research & Innovation","Research & Innovation",IF(I4="Rankings & Achievements","Institutional Reputation","Other"))))) -> Career & Alumni | Q4: =IF(OR(J4="Student Experience",J4="Campus Life",J4="Campus Facilities",J4="Student Clubs & Organizations",J4="Events",J4="Student Support Services",J4="Diversity & Inclusion",J4="International Students"),"Student Experience & Campus",IF(OR(J4="Academic Programs",J4="Admissions",J4="Scholarships & Financial Aid"),"Academic & Admissions",IF(OR(J4="Career Opportunities",J4="Alumni Success"),"Career & Alumni",IF(J4="Research & Innovation","Research & Innovation",IF(J4="Rankings & Achievements","Institutional Reputation","Other"))))) -> Student Experience & Campus | R4: =IF(K4="Informational","Informational",IF(OR(K4="Promotional",K4="Call-to-Action"),"Promotional/Conversion",IF(K4="Reputation Building","Reputation-focused","Engagement/Relationship"))) -> Engagement/Relationship | S4: =IF(COUNTIF($A$2:$A$181,A4)>1,"Duplicate","OK") -> OK | T4: =IF(COUNTIF($F$2:$F$181,F4)>1,"Duplicate","OK") -> OK | U4: =IF(AND(TEXT(C4,"mmmm")=D4,YEAR(C4)=E4),"OK","Mismatch") -> OK | V4: =IF(OR(M4="NA",N4="NA"),"Likes/comments unavailable",IF(I4=J4,"Primary and secondary themes identical","OK")) -> OK
A5: UOT004 | B5: University of Toronto | C5: 45693 | D5: February | E5: 2025 | F5: https://www.instagram.com/p/DFtOatUykUC/?utm_source=ig_web_copy_link&igsh=MzRlODBiNWFlZA== | G5: Image | H5: Yes | I5: Research & Innovation | J5: Rankings & Achievements | K5: Reputation Building | L5: Yes | M5: 1031 | N5: 16 | O5: #UofT is among the world’s top 10 universities powering global innovation in critical areas like technology, health care, sustainability and economic development, according to international data analytics company Clarivate. | P5: =IF(OR(I5="Student Experience",I5="Campus Life",I5="Campus Facilities",I5="Student Clubs & Organizations",I5="Events",I5="Student Support Services",I5="Diversity & Inclusion",I5="International Students"),"Student Experience & Campus",IF(OR(I5="Academic Programs",I5="Admissions",I5="Scholarships & Financial Aid"),"Academic & Admissions",IF(OR(I5="Career Opportunities",I5="Alumni Success"),"Career & Alumni",IF(I5="Research & Innovation","Research & Innovation",IF(I5="Rankings & Achievements","Institutional Reputation","Other"))))) -> Research & Innovation | Q5: =IF(OR(J5="Student Experience",J5="Campus Life",J5="Campus Facilities",J5="Student Clubs & Organizations",J5="Events",J5="Student Support Services",J5="Diversity & Inclusion",J5="International Students"),"Student Experience & Campus",IF(OR(J5="Academic Programs",J5="Admissions",J5="Scholarships & Financial Aid"),"Academic & Admissions",IF(OR(J5="Career Opportunities",J5="Alumni Success"),"Career & Alumni",IF(J5="Research & Innovation","Research & Innovation",IF(J5="Rankings & Achievements","Institutional Reputation","Other"))))) -> Institutional Reputation | R5: =IF(K5="Informational","Informational",IF(OR(K5="Promotional",K5="Call-to-Action"),"Promotional/Conversion",IF(K5="Reputation Building","Reputation-focused","Engagement/Relationship"))) -> Reputation-focused | S5: =IF(COUNTIF($A$2:$A$181,A5)>1,"Duplicate","OK") -> OK | T5: =IF(COUNTIF($F$2:$F$181,F5)>1,"Duplicate","OK") -> OK | U5: =IF(AND(TEXT(C5,"mmmm")=D5,YEAR(C5)=E5),"OK","Mismatch") -> OK | V5: =IF(OR(M5="NA",N5="NA"),"Likes/comments unavailable",IF(I5=J5,"Primary and secondary themes identical","OK")) -> OK
A6: UOT005 | B6: University of Toronto | C6: 45699 | D6: February | E6: 2025 | F6: https://www.instagram.com/reel/DF8FBerRF8m/?utm_source=ig_web_copy_link&igsh=MzRlODBiNWFlZA== | G6: Reel | H6: Yes | I6: Student Experience | J6: Campus Life | K6: Student Testimonial | L6: Yes | M6: 2628 | N6: 33 | O6: A day in the life of a @uoftims & #UofT PhD student, @sciencewithsajee! | P6: =IF(OR(I6="Student Experience",I6="Campus Life",I6="Campus Facilities",I6="Student Clubs & Organizations",I6="Events",I6="Student Support Services",I6="Diversity & Inclusion",I6="International Students"),"Student Experience & Campus",IF(OR(I6="Academic Programs",I6="Admissions",I6="Scholarships & Financial Aid"),"Academic & Admissions",IF(OR(I6="Career Opportunities",I6="Alumni Success"),"Career & Alumni",IF(I6="Research & Innovation","Research & Innovation",IF(I6="Rankings & Achievements","Institutional Reputation","Other"))))) -> Student Experience & Campus | Q6: =IF(OR(J6="Student Experience",J6="Campus Life",J6="Campus Facilities",J6="Student Clubs & Organizations",J6="Events",J6="Student Support Services",J6="Diversity & Inclusion",J6="International Students"),"Student Experience & Campus",IF(OR(J6="Academic Programs",J6="Admissions",J6="Scholarships & Financial Aid"),"Academic & Admissions",IF(OR(J6="Career Opportunities",J6="Alumni Success"),"Career & Alumni",IF(J6="Research & Innovation","Research & Innovation",IF(J6="Rankings & Achievements","Institutional Reputation","Other"))))) -> Student Experience & Campus | R6: =IF(K6="Informational","Informational",IF(OR(K6="Promotional",K6="Call-to-Action"),"Promotional/Conversion",IF(K6="Reputation Building","Reputation-focused","Engagement/Relationship"))) -> Engagement/Relationship | S6: =IF(COUNTIF($A$2:$A$181,A6)>1,"Duplicate","OK") -> OK | T6: =IF(COUNTIF($F$2:$F$181,F6)>1,"Duplicate","OK") -> OK | U6: =IF(AND(TEXT(C6,"mmmm")=D6,YEAR(C6)=E6),"OK","Mismatch") -> OK | V6: =IF(OR(M6="NA",N6="NA"),"Likes/comments unavailable",IF(I6=J6,"Primary and secondary themes identical","OK")) -> OK
A7: UOT006 | B7: University of Toronto | C7: 45702 | D7: February | E7: 2025 | F7: https://www.instagram.com/p/DGDu9TwRvKz/?utm_source=ig_web_copy_link&igsh=MzRlODBiNWFlZA== | G7: Carousel | H7: Yes | I7: Diversity & Inclusion | J7: Research & Innovation | K7: Emotional Storytelling | L7: Yes | M7: 1516 | N7: 9 | O7: Diagnosed with autism, he couldn’t speak or signal his thoughts. But everything changed when he learned to communicate through a letter board. What followed stunned his family. Now, he is helping #UofT neuroscientist Morgan Barense with her research @uoftpsychology using brain scans into non-speaking autism. | P7: =IF(OR(I7="Student Experience",I7="Campus Life",I7="Campus Facilities",I7="Student Clubs & Organizations",I7="Events",I7="Student Support Services",I7="Diversity & Inclusion",I7="International Students"),"Student Experience & Campus",IF(OR(I7="Academic Programs",I7="Admissions",I7="Scholarships & Financial Aid"),"Academic & Admissions",IF(OR(I7="Career Opportunities",I7="Alumni Success"),"Career & Alumni",IF(I7="Research & Innovation","Research & Innovation",IF(I7="Rankings & Achievements","Institutional Reputation","Other"))))) -> Student Experience & Campus | Q7: =IF(OR(J7="Student Experience",J7="Campus Life",J7="Campus Facilities",J7="Student Clubs & Organizations",J7="Events",J7="Student Support Services",J7="Diversity & Inclusion",J7="International Students"),"Student Experience & Campus",IF(OR(J7="Academic Programs",J7="Admissions",J7="Scholarships & Financial Aid"),"Academic & Admissions",IF(OR(J7="Career Opportunities",J7="Alumni Success"),"Career & Alumni",IF(J7="Research & Innovation","Research & Innovation",IF(J7="Rankings & Achievements","Institutional Reputation","Other"))))) -> Research & Innovation | R7: =IF(K7="Informational","Informational",IF(OR(K7="Promotional",K7="Call-to-Action"),"Promotional/Conversion",IF(K7="Reputation Building","Reputation-focused","Engagement/Relationship"))) -> Engagement/Relationship | S7: =IF(COUNTIF($A$2:$A$181,A7)>1,"Duplicate","OK") -> OK | T7: =IF(COUNTIF($F$2:$F$181,F7)>1,"Duplicate","OK") -> OK | U7: =IF(AND(TEXT(C7,"mmmm")=D7,YEAR(C7)=E7),"OK","Mismatch") -> OK | V7: =IF(OR(M7="NA",N7="NA"),"Likes/comments unavailable",IF(I7=J7,"Primary and secondary themes identical","OK")) -> OK
A8: UOT007 | B8: University of Toronto | C8: 45729 | D8: March | E8: 2025 | F8: https://www.instagram.com/reel/DHJab1PRh1X/?utm_source=ig_web_copy_link&igsh=MzRlODBiNWFlZA== | G8: Reel | H8: Yes | I8: Alumni Success | J8: Events | K8: Community Engagement | L8: Yes | M8: 1047 | N8: 73 | O8: This is @uoftstartup’s #UofTEntWeek, founder style! Follow #UofT alumna & Toothpod founder @vishar.y as she explores everything U of T Entrepreneurship has to offer, including her personal advice on getting started. | P8: =IF(OR(I8="Student Experience",I8="Campus Life",I8="Campus Facilities",I8="Student Clubs & Organizations",I8="Events",I8="Student Support Services",I8="Diversity & Inclusion",I8="International Students"),"Student Experience & Campus",IF(OR(I8="Academic Programs",I8="Admissions",I8="Scholarships & Financial Aid"),"Academic & Admissions",IF(OR(I8="Career Opportunities",I8="Alumni Success"),"Career & Alumni",IF(I8="Research & Innovation","Research & Innovation",IF(I8="Rankings & Achievements","Institutional Reputation","Other"))))) -> Career & Alumni | Q8: =IF(OR(J8="Student Experience",J8="Campus Life",J8="Campus Facilities",J8="Student Clubs & Organizations",J8="Events",J8="Student Support Services",J8="Diversity & Inclusion",J8="International Students"),"Student Experience & Campus",IF(OR(J8="Academic Programs",J8="Admissions",J8="Scholarships & Financial Aid"),"Academic & Admissions",IF(OR(J8="Career Opportunities",J8="Alumni Success"),"Career & Alumni",IF(J8="Research & Innovation","Research & Innovation",IF(J8="Rankings & Achievements","Institutional Reputation","Other"))))) -> Student Experience & Campus | R8: =IF(K8="Informational","Informational",IF(OR(K8="Promotional",K8="Call-to-Action"),"Promotional/Conversion",IF(K8="Reputation Building","Reputation-focused","Engagement/Relationship"))) -> Engagement/Relationship | S8: =IF(COUNTIF($A$2:$A$181,A8)>1,"Duplicate","OK") -> OK | T8: =IF(COUNTIF($F$2:$F$181,F8)>1,"Duplicate","OK") -> OK | U8: =IF(AND(TEXT(C8,"mmmm")=D8,YEAR(C8)=E8),"OK","Mismatch") -> OK | V8: =IF(OR(M8="NA",N8="NA"),"Likes/comments unavailable",IF(I8=J8,"Primary and secondary themes identical","OK")) -> OK
A9: UOT008 | B9: University of Toronto | C9: 45733 | D9: March | E9: 2025 | F9: https://www.instagram.com/reel/DHT7iTYxaMb/?utm_source=ig_web_copy_link&igsh=MzRlODBiNWFlZA== | G9: Reel | H9: Yes | I9: Diversity & Inclusion | J9: Alumni Success | K9: Inspirational | L9: No | M9: 2463 | N9: 59 | O9: 11 languages? 🤯 Recent #UofT alumni and hyperpolyglot @xinyi_limx shows us her appreciation for the diversity and rich culture that Toronto has to offer. #MyUofT | P9: =IF(OR(I9="Student Experience",I9="Campus Life",I9="Campus Facilities",I9="Student Clubs & Organizations",I9="Events",I9="Student Support Services",I9="Diversity & Inclusion",I9="International Students"),"Student Experience & Campus",IF(OR(I9="Academic Programs",I9="Admissions",I9="Scholarships & Financial Aid"),"Academic & Admissions",IF(OR(I9="Career Opportunities",I9="Alumni Success"),"Career & Alumni",IF(I9="Research & Innovation","Research & Innovation",IF(I9="Rankings & Achievements","Institutional Reputation","Other"))))) -> Student Experience & Campus | Q9: =IF(OR(J9="Student Experience",J9="Campus Life",J9="Campus Facilities",J9="Student Clubs & Organizations",J9="Events",J9="Student Support Services",J9="Diversity & Inclusion",J9="International Students"),"Student Experience & Campus",IF(OR(J9="Academic Programs",J9="Admissions",J9="Scholarships & Financial Aid"),"Academic & Admissions",IF(OR(J9="Career Opportunities",J9="Alumni Success"),"Career & Alumni",IF(J9="Research & Innovation","Research & Innovation",IF(J9="Rankings & Achievements","Institutional Reputation","Other"))))) -> Career & Alumni | R9: =IF(K9="Informational","Informational",IF(OR(K9="Promotional",K9="Call-to-Action"),"Promotional/Conversion",IF(K9="Reputation Building","Reputation-focused","Engagement/Relationship"))) -> Engagement/Relationship | S9: =IF(COUNTIF($A$2:$A$181,A9)>1,"Duplicate","OK") -> OK | T9: =IF(COUNTIF($F$2:$F$181,F9)>1,"Duplicate","OK") -> OK | U9: =IF(AND(TEXT(C9,"mmmm")=D9,YEAR(C9)=E9),"OK","Mismatch") -> OK | V9: =IF(OR(M9="NA",N9="NA"),"Likes/comments unavailable",IF(I9=J9,"Primary and secondary themes identical","OK")) -> OK
A10: UOT009 | B10: University of Toronto | C10: 45736 | D10: March | E10: 2025 | F10: https://www.instagram.com/reel/DHbOdPjyScp/?utm_source=ig_web_copy_link&igsh=MzRlODBiNWFlZA== | G10: Reel | H10: Yes | I10: Admissions | J10: Student Support Services | K10: Call-to-Action | L10: Yes | M10: 537 | N10: 11 | O10: Did you get an acceptance letter from #UofT? Congratulations! 🎉 We want to see your excitement to start your journey with us next year! DM us or post a video with #UofTBound tagging @futureuoft, @uoft and your campus @utsc or @uoftmississauga for your chance to be featured on our accounts! | P10: =IF(OR(I10="Student Experience",I10="Campus Life",I10="Campus Facilities",I10="Student Clubs & Organizations",I10="Events",I10="Student Support Services",I10="Diversity & Inclusion",I10="International Students"),"Student Experience & Campus",IF(OR(I10="Academic Programs",I10="Admissions",I10="Scholarships & Financial Aid"),"Academic & Admissions",IF(OR(I10="Career Opportunities",I10="Alumni Success"),"Career & Alumni",IF(I10="Research & Innovation","Research & Innovation",IF(I10="Rankings & Achievements","Institutional Reputation","Other"))))) -> Academic & Admissions | Q10: =IF(OR(J10="Student Experience",J10="Campus Life",J10="Campus Facilities",J10="Student Clubs & Organizations",J10="Events",J10="Student Support Services",J10="Diversity & Inclusion",J10="International Students"),"Student Experience & Campus",IF(OR(J10="Academic Programs",J10="Admissions",J10="Scholarships & Financial Aid"),"Academic & Admissions",IF(OR(J10="Career Opportunities",J10="Alumni Success"),"Career & Alumni",IF(J10="Research & Innovation","Research & Innovation",IF(J10="Rankings & Achievements","Institutional Reputation","Other"))))) -> Student Experience & Campus | R10: =IF(K10="Informational","Informational",IF(OR(K10="Promotional",K10="Call-to-Action"),"Promotional/Conversion",IF(K10="Reputation Building","Reputation-focused","Engagement/Relationship"))) -> Promotional/Conversion | S10: =IF(COUNTIF($A$2:$A$181,A10)>1,"Duplicate","OK") -> OK | T10: =IF(COUNTIF($F$2:$F$181,F10)>1,"Duplicate","OK") -> OK | U10: =IF(AND(TEXT(C10,"mmmm")=D10,YEAR(C10)=E10),"OK","Mismatch") -> OK | V10: =IF(OR(M10="NA",N10="NA"),"Likes/comments unavailable",IF(I10=J10,"Primary and secondary themes identical","OK")) -> OK
A11: UOT010 | B11: University of Toronto | C11: 45748 | D11: April | E11: 2025 | F11: https://www.instagram.com/p/DH6YEVQOf-Z/?utm_source=ig_web_copy_link&igsh=MzRlODBiNWFlZA== | G11: Carousel | H11: Yes | I11: Admissions | J11: Academic Programs | K11: Promotional | L11: Yes | M11: 2233 | N11: 20 | O11: #UTM March Open House was a memorable day filled with opportunities! 💙 . | P11: =IF(OR(I11="Student Experience",I11="Campus Life",I11="Campus Facilities",I11="Student Clubs & Organizations",I11="Events",I11="Student Support Services",I11="Diversity & Inclusion",I11="International Students"),"Student Experience & Campus",IF(OR(I11="Academic Programs",I11="Admissions",I11="Scholarships & Financial Aid"),"Academic & Admissions",IF(OR(I11="Career Opportunities",I11="Alumni Success"),"Career & Alumni",IF(I11="Research & Innovation","Research & Innovation",IF(I11="Rankings & Achievements","Institutional Reputation","Other"))))) -> Academic & Admissions | Q11: =IF(OR(J11="Student Experience",J11="Campus Life",J11="Campus Facilities",J11="Student Clubs & Organizations",J11="Events",J11="Student Support Services",J11="Diversity & Inclusion",J11="International Students"),"Student Experience & Campus",IF(OR(J11="Academic Programs",J11="Admissions",J11="Scholarships & Financial Aid"),"Academic & Admissions",IF(OR(J11="Career Opportunities",J11="Alumni Success"),"Career & Alumni",IF(J11="Research & Innovation","Research & Innovation",IF(J11="Rankings & Achievements","Institutional Reputation","Other"))))) -> Academic & Admissions | R11: =IF(K11="Informational","Informational",IF(OR(K11="Promotional",K11="Call-to-Action"),"Promotional/Conversion",IF(K11="Reputation Building","Reputation-focused","Engagement/Relationship"))) -> Promotional/Conversion | S11: =IF(COUNTIF($A$2:$A$181,A11)>1,"Duplicate","OK") -> OK | T11: =IF(COUNTIF($F$2:$F$181,F11)>1,"Duplicate","OK") -> OK | U11: =IF(AND(TEXT(C11,"mmmm")=D11,YEAR(C11)=E11),"OK","Mismatch") -> OK | V11: =IF(OR(M11="NA",N11="NA"),"Likes/comments unavailable",IF(I11=J11,"Primary and secondary themes identical","OK")) -> OK
A12: UOT011 | B12: University of Toronto | C12: 45751 | D12: =IF(C12="","",TEXT(C12,"mmmm")) -> April | E12: =IF(C12="","",YEAR(C12)) -> 2025 | F12: https://www.instagram.com/reel/DIB-jGhRYlB/?utm_source=ig_web_copy_link&igsh=MzRlODBiNWFlZA== | G12: Reel | H12: Yes | I12: Campus Facilities | J12: Student Experience | K12: Emotional Storytelling | L12: Yes | M12: 1645 | N12: 14 | O12: After being named #UofT’s 17th president on March 26, Melanie Woodin met with students, staff, faculty and senior leaders across U of T’s three campuses during a whirlwind two-day tour. 💙 | P12: =IF(OR(I12="Student Experience",I12="Campus Life",I12="Campus Facilities",I12="Student Clubs & Organizations",I12="Events",I12="Student Support Services",I12="Diversity & Inclusion",I12="International Students"),"Student Experience & Campus",IF(OR(I12="Academic Programs",I12="Admissions",I12="Scholarships & Financial Aid"),"Academic & Admissions",IF(OR(I12="Career Opportunities",I12="Alumni Success"),"Career & Alumni",IF(I12="Research & Innovation","Research & Innovation",IF(I12="Rankings & Achievements","Institutional Reputation","Other"))))) -> Student Experience & Campus | Q12: =IF(OR(J12="Student Experience",J12="Campus Life",J12="Campus Facilities",J12="Student Clubs & Organizations",J12="Events",J12="Student Support Services",J12="Diversity & Inclusion",J12="International Students"),"Student Experience & Campus",IF(OR(J12="Academic Programs",J12="Admissions",J12="Scholarships & Financial Aid"),"Academic & Admissions",IF(OR(J12="Career Opportunities",J12="Alumni Success"),"Career & Alumni",IF(J12="Research & Innovation","Research & Innovation",IF(J12="Rankings & Achievements","Institutional Reputation","Other"))))) -> Student Experience & Campus | R12: =IF(K12="Informational","Informational",IF(OR(K12="Promotional",K12="Call-to-Action"),"Promotional/Conversion",IF(K12="Reputation Building","Reputation-focused","Engagement/Relationship"))) -> Engagement/Relationship | S12: =IF(COUNTIF($A$2:$A$181,A12)>1,"Duplicate","OK") -> OK | T12: =IF(COUNTIF($F$2:$F$181,F12)>1,"Duplicate","OK") -> OK | U12: =IF(AND(TEXT(C12,"mmmm")=D12,YEAR(C12)=E12),"OK","Mismatch") -> OK | V12: =IF(OR(M12="NA",N12="NA"),"Likes/comments unavailable",IF(I12=J12,"Primary and secondary themes identical","OK")) -> OK
A13: UOT012 | B13: University of Toronto | C13: 45772 | D13: April | E13: 2025 | F13: https://www.instagram.com/reel/DI37WR7tdJv/?utm_source=ig_web_copy_link&igsh=MzRlODBiNWFlZA== | G13: Reel | H13: Yes | I13: Admissions | J13: Student Experience | K13: Emotional Storytelling | L13: No | M13: 3952 | N13: 56 | O13: his is the moment when @dentistrywithdal found out she was #UofTBound! 💙 She’ll be attending @uoftdentistry this fall. We’re so excited to have you at #UofT, @daliaprovad! | P13: =IF(OR(I13="Student Experience",I13="Campus Life",I13="Campus Facilities",I13="Student Clubs & Organizations",I13="Events",I13="Student Support Services",I13="Diversity & Inclusion",I13="International Students"),"Student Experience & Campus",IF(OR(I13="Academic Programs",I13="Admissions",I13="Scholarships & Financial Aid"),"Academic & Admissions",IF(OR(I13="Career Opportunities",I13="Alumni Success"),"Career & Alumni",IF(I13="Research & Innovation","Research & Innovation",IF(I13="Rankings & Achievements","Institutional Reputation","Other"))))) -> Academic & Admissions | Q13: =IF(OR(J13="Student Experience",J13="Campus Life",J13="Campus Facilities",J13="Student Clubs & Organizations",J13="Events",J13="Student Support Services",J13="Diversity & Inclusion",J13="International Students"),"Student Experience & Campus",IF(OR(J13="Academic Programs",J13="Admissions",J13="Scholarships & Financial Aid"),"Academic & Admissions",IF(OR(J13="Career Opportunities",J13="Alumni Success"),"Career & Alumni",IF(J13="Research & Innovation","Research & Innovation",IF(J13="Rankings & Achievements","Institutional Reputation","Other"))))) -> Student Experience & Campus | R13: =IF(K13="Informational","Informational",IF(OR(K13="Promotional",K13="Call-to-Action"),"Promotional/Conversion",IF(K13="Reputation Building","Reputation-focused","Engagement/Relationship"))) -> Engagement/Relationship | S13: =IF(COUNTIF($A$2:$A$181,A13)>1,"Duplicate","OK") -> OK | T13: =IF(COUNTIF($F$2:$F$181,F13)>1,"Duplicate","OK") -> OK | U13: =IF(AND(TEXT(C13,"mmmm")=D13,YEAR(C13)=E13),"OK","Mismatch") -> OK | V13: =IF(OR(M13="NA",N13="NA"),"Likes/comments unavailable",IF(I13=J13,"Primary and secondary themes identical","OK")) -> OK
A14: UOT013 | B14: University of Toronto | C14: 45783 | D14: May | E14: 2025 | F14: https://www.instagram.com/reel/DJUeIo4Jy8I/?utm_source=ig_web_copy_link&igsh=MzRlODBiNWFlZA== | G14: Reel | H14: Yes | I14: Events | J14: Student Experience | K14: Emotional Storytelling | L14: Yes | M14: 3672 | N14: 59 | O14: s spring begins to bloom in southern Ontario, thousands of students from across #UofT’s three campuses are preparing to close their laptops, don gowns and hoods – and walk across the #UofTGrad25 stage in Convocation Hall. 📜 Read the story via our link in bio or at uoft.me/sc25 | P14: =IF(OR(I14="Student Experience",I14="Campus Life",I14="Campus Facilities",I14="Student Clubs & Organizations",I14="Events",I14="Student Support Services",I14="Diversity & Inclusion",I14="International Students"),"Student Experience & Campus",IF(OR(I14="Academic Programs",I14="Admissions",I14="Scholarships & Financial Aid"),"Academic & Admissions",IF(OR(I14="Career Opportunities",I14="Alumni Success"),"Career & Alumni",IF(I14="Research & Innovation","Research & Innovation",IF(I14="Rankings & Achievements","Institutional Reputation","Other"))))) -> Student Experience & Campus | Q14: =IF(OR(J14="Student Experience",J14="Campus Life",J14="Campus Facilities",J14="Student Clubs & Organizations",J14="Events",J14="Student Support Services",J14="Diversity & Inclusion",J14="International Students"),"Student Experience & Campus",IF(OR(J14="Academic Programs",J14="Admissions",J14="Scholarships & Financial Aid"),"Academic & Admissions",IF(OR(J14="Career Opportunities",J14="Alumni Success"),"Career & Alumni",IF(J14="Research & Innovation","Research & Innovation",IF(J14="Rankings & Achievements","Institutional Reputation","Other"))))) -> Student Experience & Campus | R14: =IF(K14="Informational","Informational",IF(OR(K14="Promotional",K14="Call-to-Action"),"Promotional/Conversion",IF(K14="Reputation Building","Reputation-focused","Engagement/Relationship"))) -> Engagement/Relationship | S14: =IF(COUNTIF($A$2:$A$181,A14)>1,"Duplicate","OK") -> OK | T14: =IF(COUNTIF($F$2:$F$181,F14)>1,"Duplicate","OK") -> OK | U14: =IF(AND(TEXT(C14,"mmmm")=D14,YEAR(C14)=E14),"OK","Mismatch") -> OK | V14: =IF(OR(M14="NA",N14="NA"),"Likes/comments unavailable",IF(I14=J14,"Primary and secondary themes identical","OK")) -> OK
A15: UOT014 | B15: University of Toronto | C15: 45792 | D15: May | E15: 2025 | F15: https://www.instagram.com/reel/DJrhRH1t1wM/?utm_source=ig_web_copy_link&igsh=MzRlODBiNWFlZA== | G15: Reel | H15: Yes | I15: Student Experience | J15: Campus Life | K15: Student Testimonial | L15: Yes | M15: 971 | N15: 27 | O15: In this #MyUofT, follow @gabriel_vargas.glz through a day in the life as a 2nd year BBA Co-op Management student at @utsc! As an international student from Mexico, Gabriel shows us his home at Harmony Commons and around #UTSC. 🇲🇽 #UofT | P15: =IF(OR(I15="Student Experience",I15="Campus Life",I15="Campus Facilities",I15="Student Clubs & Organizations",I15="Events",I15="Student Support Services",I15="Diversity & Inclusion",I15="International Students"),"Student Experience & Campus",IF(OR(I15="Academic Programs",I15="Admissions",I15="Scholarships & Financial Aid"),"Academic & Admissions",IF(OR(I15="Career Opportunities",I15="Alumni Success"),"Career & Alumni",IF(I15="Research & Innovation","Research & Innovation",IF(I15="Rankings & Achievements","Institutional Reputation","Other"))))) -> Student Experience & Campus | Q15: =IF(OR(J15="Student Experience",J15="Campus Life",J15="Campus Facilities",J15="Student Clubs & Organizations",J15="Events",J15="Student Support Services",J15="Diversity & Inclusion",J15="International Students"),"Student Experience & Campus",IF(OR(J15="Academic Programs",J15="Admissions",J15="Scholarships & Financial Aid"),"Academic & Admissions",IF(OR(J15="Career Opportunities",J15="Alumni Success"),"Career & Alumni",IF(J15="Research & Innovation","Research & Innovation",IF(J15="Rankings & Achievements","Institutional Reputation","Other"))))) -> Student Experience & Campus | R15: =IF(K15="Informational","Informational",IF(OR(K15="Promotional",K15="Call-to-Action"),"Promotional/Conversion",IF(K15="Reputation Building","Reputation-focused","Engagement/Relationship"))) -> Engagement/Relationship | S15: =IF(COUNTIF($A$2:$A$181,A15)>1,"Duplicate","OK") -> OK | T15: =IF(COUNTIF($F$2:$F$181,F15)>1,"Duplicate","OK") -> OK | U15: =IF(AND(TEXT(C15,"mmmm")=D15,YEAR(C15)=E15),"OK","Mismatch") -> OK | V15: =IF(OR(M15="NA",N15="NA"),"Likes/comments unavailable",IF(I15=J15,"Primary and secondary themes identical","OK")) -> OK
A16: UOT015 | B16: University of Toronto | C16: 45804 | D16: May | E16: 2025 | F16: https://www.instagram.com/p/DKKXdHbtaSE/?utm_source=ig_web_copy_link&igsh=MzRlODBiNWFlZA== | G16: Image | H16: Yes | I16: Student Experience | J16: Academic Programs | K16: Student Testimonial | L16: Yes | M16: 1006 | N16: 9 | O16: Having made the difficult decision to drop out of high school several years earlier, Moosewaypayo entered U of T through the Millie Rotman Shime Academic Bridging Program at @woodsworth.college @uoftartsci, which was recommended to her by a friend. The program allows students who wouldn’t otherwise meet U of T’s admission requirements to qualify for honours bachelor of arts and bachelor of science programs. | P16: =IF(OR(I16="Student Experience",I16="Campus Life",I16="Campus Facilities",I16="Student Clubs & Organizations",I16="Events",I16="Student Support Services",I16="Diversity & Inclusion",I16="International Students"),"Student Experience & Campus",IF(OR(I16="Academic Programs",I16="Admissions",I16="Scholarships & Financial Aid"),"Academic & Admissions",IF(OR(I16="Career Opportunities",I16="Alumni Success"),"Career & Alumni",IF(I16="Research & Innovation","Research & Innovation",IF(I16="Rankings & Achievements","Institutional Reputation","Other"))))) -> Student Experience & Campus | Q16: =IF(OR(J16="Student Experience",J16="Campus Life",J16="Campus Facilities",J16="Student Clubs & Organizations",J16="Events",J16="Student Support Services",J16="Diversity & Inclusion",J16="International Students"),"Student Experience & Campus",IF(OR(J16="Academic Programs",J16="Admissions",J16="Scholarships & Financial Aid"),"Academic & Admissions",IF(OR(J16="Career Opportunities",J16="Alumni Success"),"Career & Alumni",IF(J16="Research & Innovation","Research & Innovation",IF(J16="Rankings & Achievements","Institutional Reputation","Other"))))) -> Academic & Admissions | R16: =IF(K16="Informational","Informational",IF(OR(K16="Promotional",K16="Call-to-Action"),"Promotional/Conversion",IF(K16="Reputation Building","Reputation-focused","Engagement/Relationship"))) -> Engagement/Relationship | S16: =IF(COUNTIF($A$2:$A$181,A16)>1,"Duplicate","OK") -> OK | T16: =IF(COUNTIF($F$2:$F$181,F16)>1,"Duplicate","OK") -> OK | U16: =IF(AND(TEXT(C16,"mmmm")=D16,YEAR(C16)=E16),"OK","Mismatch") -> OK | V16: =IF(OR(M16="NA",N16="NA"),"Likes/comments unavailable",IF(I16=J16,"Primary and secondary themes identical","OK")) -> OK
